/**************************************************************************** **
 * 下面是一个实例，抛出一个除以零的异常，并在 catch 块中捕获该异常。
 **************************************************************************** **/

#include <iostream>
using namespace std;

double division(int a, int b)
{
	if( b == 0 )
	{
		throw "Division by zero condition!";
	}
	return (a/b);
}

int main ()
{
	int x = 50;
	int y = 0;
	double z = 0;

	try {
		z = division(x, y);   //保护代码
		cout << z << endl;
	}catch (const char* msg) {
		cerr << msg << endl;
	}

	return 0;
}

